Workbook
Name ABRIL: #REF!
Name AGOSTO: #REF!
Name AnoSelecionado: #REF!
Name Comisiones: #REF!
Name Comisiones_Vs._Primas_Netas_Cobradas: #REF!
Name ComisionesEmpresaSelec: #REF!
Name CostoReaseguroPorcent: #REF!
Name CU: #REF!
Name DICIEMBRE: #REF!
Name Empresa1: #REF!
Name Empresa10: #REF!
Name Empresa11: #REF!
Name Empresa12: #REF!
Name Empresa13: #REF!
Name Empresa14: #REF!
Name Empresa15: #REF!
Name Empresa16: #REF!
Name Empresa17: #REF!
Name Empresa18: #REF!
Name Empresa19: #REF!
Name Empresa2: #REF!
Name Empresa20: #REF!
Name Empresa3: #REF!
Name Empresa4: #REF!
Name Empresa5: #REF!
Name Empresa6: #REF!
Name Empresa7: #REF!
Name Empresa8: #REF!
Name Empresa9: #REF!
Name Empresaselec: #REF!
Name ENERO: #REF!
Name FEBRERO: #REF!
Name Fotos: INDEX(LOGOS!$D$2:$D$52,MATCH([1]Hoja1!$G$5,LOGOS!$A$2:$A$52,0))
Name Gastos_de_Administración: #REF!
Name Gastos_de_Administración_Vs._Primas_Netas_Cobradas: #REF!
Name Gastos_de_AdministraciónEmpresaSelec: #REF!
Name Gastos_de_Adquisición: #REF!
Name Gastos_de_Adquisición_Vs._Primas_Netas_Cobradas: #REF!
Name Gastos_de_AdquisiciónEmpresaSelec: #REF!
Name Indice_de_Cobertura_de_Reservas: #REF!
Name JULIO: #REF!
Name JUNIO: #REF!
Name LOGOS: INDEX(LOGOS!$D$2:$D$52,MATCH(#REF!,LOGOS!$C$2:$C$52,0))
Name LOGOS2: INDEX(LOGOS!$D$2:$D$52,MATCH(#REF!,LOGOS!$C$2:$C$52,0))
Name LugarPNC: #REF!
Name MARZO: #REF!
Name MAYO: #REF!
Name Mes_Elegido: #REF!
Name NOVIEMBRE: #REF!
Name OCTUBRE: #REF!
Name Participacion: #REF!
Name PNC: #REF!
Name PNCEmpresaSelec: #REF!
Name PNCUSD: #REF!
Name PNCUSDANT: #REF!
Name PNDUSDANT: #REF!
Name primaje1: #REF!
Name primaje10: #REF!
Name primaje11: #REF!
Name primaje12: #REF!

Sheet Compilado
A4: Registre los datos compilados
A6: NumerodeInscripciondelaEmpresa | B6: Nombre Empresa | C6: PrimasNetasCobradas | D6: SiniestrosPagados_NetosdeSalvamento | E6: SiniestrosPendientes | F6: ComisionesyGastosdeAdquision | G6: Gastosdeadministracion | H6: SaldodeOperaciones | I6: InversionesAptas | J6: InversionesNoAptas | K6: ReservasTecnicas | L6: ReservasdePrimas | M6: RetenciondePrimasaCargodeReaseguradoresRetrocesionarios | N6: RetenciondelasReservasdePrestacionesySiniestrosPendientes | O6: RTE_REF_RTEA | P6: ResultadoTecnicoBruto | Q6: ResultadodelReaseguroCedido | R6: ResultadoTecnicoNeto | S6: ResultadodeGestionGeneral | T6: ProductodeInversiones | U6: AjustedeValores_Ingresos | V6: IngresosporFideicomiso | W6: IngresosporServicios | X6: BeneficiosDiversos | Y6: GastosdeAdministración_GestiónGeneral | Z6: EgresosFinancieros | AA6: AjustedeReservasdeProvisión | AB6: AjustedeValoresyOtrosActivos | AC6: PérdidasenActivos | AD6: EgresosporFideicomiso | AE6: EgresosporServicios | AF6: OtrosEgresos | AG6: ReservasPrimasBrutas | AH6: ReservasdeSiniestrosPendientesBrutas | AI6: ReservasTécnicasdelEjercicioBrutas | AJ6: ReservasTécnicasdelEjercicioAnteriorBrutas | AK6: ReintegroconExperienciaFavorable | AL6: MontodeSuficienciaoInsuficienciaenlaCoberturadeReserva | AM6: IndicedeCoberturadeReservas | AN6: Comisiones | AO6: GastosdeAdquision | AP6: Total GeneralPDev | AQ6: TotalGenralSI | AR6: CapitalSocial | AS6: Fecha | AT6: MES | AU6: Saldo "+"/"-" | AV6: AÑO | AW6: NombreCorto | AX6: TasaPromedio | AY6: TasaCierre
A7: 32 | B7: Adriática de Seguros, C.A. | C7: 0 | D7: 0 | E7: 1e-08 | F7: 0 | G7: 4084.4249 | H7: 0 | I7: 742825.32 | J7: 3999.8323 | K7: 0.01136762 | L7: 0.01136761 | M7: 0 | N7: 0 | O7: 0.01136761 | P7: -4084.4363 | Q7: 0 | R7: -4084.4363 | S7: 4084.4363 | T7: 0 | U7: 0 | V7: 0 | W7: 0 | X7: 4169.6066 | Y7: 83.350097 | Z7: 1.7284438 | AA7: 0.09174916 | AB7: 0 | AC7: 0 | AD7: 0 | AE7: 0 | AF7: 0 | AG7: 0.01136761 | AH7: 1e-08 | AI7: 0.01136761 | AJ7: 0 | AK7: 0 | AL7: 742825.31 | AM7: 65.345721 | AN7: 0 | AO7: 0 | AP7: -0.01136761 | AQ7: 0 | AS7: 44227 | AT7: ENERO | AU7: Positivo | AV7: 2021 | AW7: ADRIÁTICA C.A. | AX7: 1.51 | AY7: 1.82
A8: 107 | B8: Altamira C.A., Seguros | C8: 168982.13 | D8: 28771.33 | E8: 66412.43 | F8: 32744.89 | G8: 46299.31 | H8: 2647.96 | I8: 674389.29 | J8: 305094.21 | K8: 192773.91 | L8: 126361.48 | M8: 515683.51 | N8: 0 | O8: 52630.75 | P8: 8535.85 | Q8: -57900.06 | R8: -49364.21 | S8: 52012.17 | T8: 429.11 | U8: 0 | V8: 0 | W8: 0 | X8: 57159.57 | Y8: 944.88 | Z8: 4578.86 | AA8: 0 | AB8: 52.77 | AC8: 0 | AD8: 0 | AE8: 0 | AF8: 0 | AG8: 642045 | AH8: 66412.43 | AI8: 708159.84 | AJ8: 655529.09 | AK8: 0 | AL8: 481615.38 | AM8: 3.4983432 | AN8: 18262.88 | AO8: 14482 | AP8: 107736.56 | AQ8: 20156.53 | AS8: 44227 | AT8: ENERO | AU8: Positivo | AV8: 2021 | AW8: ALTAMIRA C.A. | AX8: 1.51 | AY8: 1.82
A9: 66 | B9: American International, C.A. de Seguros | C9: 203938.17 | D9: 309858.9 | E9: 309.66 | F9: 16357.67 | G9: 90856.02 | H9: -19748.53 | I9: 1308860.8 | J9: 11475649 | K9: 574.92 | L9: 265.26 | M9: 93857.63 | N9: 14508.84 | O9: 40214.42 | P9: -253348.84 | Q9: 251025.9 | R9: -2322.94 | S9: -17425.6 | T9: 0.06 | U9: 0 | V9: 0 | W9: 0 | X9: 8093942.8 | Y9: 1824.32 | Z9: 2071.34 | AA9: 758.5 | AB9: 3.45 | AC9: 0 | AD9: 0 | AE9: 0 | AF9: 8106710.9 | AG9: 94122.89 | AH9: 14818.5 | AI9: 108921.73 | AJ9: 68707.31 | AK9: 0 | AL9: 1308285.9 | AM9: 2276.5965 | AN9: 16357.67 | AO9: 0 | AP9: 178232.88 | AQ9: 324368.02 | AS9: 44227 | AT9: ENERO | AU9: Negativo | AV9: 2021 | AW9: A.I.G. C.A. | AX9: 1.51 | AY9: 1.82
A10: 44 | B10: Andes C.A., Seguros | C10: 246928.41 | D10: 39898.67 | E10: 147435.18 | F10: 33427.73 | G10: 60313.04 | H10: 899.41 | I10: 1409163.4 | J10: 573077.77 | K10: 523742.31 | L10: 376166.53 | M10: 1489.52 | N10: 154 | O10: 200102.18 | P10: -86813.21 | Q10: -220.09 | R10: -87033.3 | S10: 87932.72 | T10: 0.09 | U10: 0 | V10: 0 | W10: 0 | X10: 99496.19 | Y10: 1230.88 | Z10: 186.45 | AA10: 9239.49 | AB10: 76.65 | AC10: 0 | AD10: 0 | AE10: 0 | AF10: 830.1 | AG10: 377656.06 | AH10: 147589.18 | AI10: 524486.26 | AJ10: 324473.65 | AK10: 89.57 | AL10: 885421.05 | AM10: 2.6905662 | AN10: 25987.72 | AO10: 7440.01 | AP10: 141612.51 | AQ10: 134684.95 | AS10: 44227 | AT10: ENERO | AU10: Positivo | AV10: 2021 | AW10: ANDES C.A. | AX10: 1.51 | AY10: 1.82
A11: 113 | B11: Aseguradora Nacional Unida Uniseguros, S.A. | C11: 17979.16 | D11: 0 | E11: 697.46 | F11: 1182.41 | G11: 14066.91 | H11: 344167.35 | I11: 4889941.7 | J11: 883307.32 | K11: 61477.34 | L11: 30915.73 | M11: 38330.68 | N11: 0 | O11: 15197.38 | P11: -12467.54 | Q11: 758.76 | R11: -11708.78 | S11: 355876.14 | T11: 11.83 | U11: 0 | V11: 0 | W11: 0 | X11: 357165.1 | Y11: 287.08 | Z11: 832.69 | AA11: 98.88 | AB11: 33.45 | AC11: 0 | AD11: 0 | AE11: 0 | AF11: 48.68 | AG11: 69246.4 | AH11: 697.46 | AI11: 69217.88 | AJ11: 54020.5 | AK11: 0 | AL11: 4828464.4 | AM11: 79.540555 | AN11: 656.86 | AO11: 525.55 | AP11: 2781.76 | AQ11: 0.01 | AS11: 44227 | AT11: ENERO | AU11: Positivo | AV11: 2021 | AW11: UNISEGUROS S.A. | AX11: 1.51 | AY11: 1.82
A12: 98 | B12: Atrio Seguros S.A. | C12: 1033456.5 | D12: 298403.57 | E12: 218345.18 | F12: 223089.82 | G12: 383256.93 | H12: 7135.1 | I12: 1022930.2 | J12: 737928.98 | K12: 919614.59 | L12: 701269.41 | M12: 1501190.8 | N12: 1124115.8 | O12: 1260479.9 | P12: -1131773.7 | Q12: 965682.32 | R12: -166091.42 | S12: 173226.51 | T12: 2344.5 | U12: 1475.46 | V12: 0 | W12: 0 | X12: 290884.82 | Y12: 5155.45 | Z12: 26925.02 | AA12: 15623.71 | AB12: 846.83 | AC12: 0 | AD12: 0 | AE12: 0 | AF12: 72927.28 | AG12: 2202460.2 | AH12: 1342461 | AI12: 3544699.1 | AJ12: 2284219.3 | AK12: 0 | AL12: 103315.57 | AM12: 1.1123466 | AN12: 137897.97 | AO12: 85191.85 | AP12: 421962.65 | AQ12: 947389.62 | AS12: 44227 | AT12: ENERO | AU12: Positivo | AV12: 2021 | AW12: ATRIO S.A. | AX12: 1.51 | AY12: 1.82
A13: 1 | B13: Ávila C.A., de Seguros | C13: 62608.11 | D13: 4262.47 | E13: 3052.09 | F13: 8114.33 | G13: 25175.81 | H13: 97.58 | I13: 43580.27 | J13: 56215.87 | K13: 21163.05 | L13: 18110.96 | M13: 104245.39 | N13: 2.05 | O13: 37781.7 | P13: -12726.2 | Q13: -3866.69 | R13: -16592.89 | S13: 16690.47 | T13: 451.41 | U13: 0 | V13: 0 | W13: 0 | X13: 17866.26 | Y13: 498.95 | Z13: 1065.7 | AA13: 58.92 | AB13: 3.62 | AC13: 0 | AD13: 0 | AE13: 0 | AF13: 0 | AG13: 122356.35 | AH13: 3054.14 | AI13: 125137.84 | AJ13: 87356.14 | AK13: 0 | AL13: 22417.22 | AM13: 2.0592623 | AN13: 4899.08 | AO13: 3215.25 | AP13: 27880.55 | AQ13: 7316.62 | AS13: 44227 | AT13: ENERO | AU13: Positivo | AV13: 2021 | AW13: ÁVILA C.A. | AX13: 1.51 | AY13: 1.82
A14: 109 | B14: Banesco Seguros C.A. | C14: 1688390.6 | D14: 550561.69 | E14: 771786.64 | F14: 273735.59 | G14: 338104.24 | H14: 3337.83 | I14: 34859480 | J14: 2968549.1 | K14: 2381498.1 | L14: 1543510.3 | M14: 268808.18 | N14: 5011615.9 | O14: 3196705.4 | P14: -2670716.3 | Q14: 1802592.1 | R14: -868124.18 | S14: 871462.02 | T14: 11110.98 | U14: 0 | V14: 0 | W14: 11091.31 | X14: 987764.84 | Y14: 5701.63 | Z14: 0 | AA14: 29533.85 | AB14: 359.36 | AC14: 0 | AD14: 0 | AE14: 0 | AF14: 102910.26 | AG14: 1812318.5 | AH14: 5783402.5 | AI14: 7585824.4 | AJ14: 4389119 | AK14: 0 | AL14: 32477982 | AM14: 14.637627 | AN14: 121731.57 | AO14: 152004.02 | AP14: 771029.97 | AQ14: 2829906.4 | AS14: 44227 | AT14: ENERO | AU14: Positivo | AV14: 2021 | AW14: BANESCO C.A. | AX14: 1.51 | AY14: 1.82
A15: 25 | B15: BBVA Seguros,C.A. | C15: 138687.95 | D15: 22313 | E15: 12653.72 | F15: 0 | G15: 78723.47 | H15: 133334.16 | I15: 294309.05 | J15: 20092674 | K15: 185483.26 | L15: 172829.54 | M15: 0 | N15: 0 | O15: 54156.01 | P15: -16504.53 | Q15: -10.59 | R15: -16515.12 | S15: 149849.28 | T15: 57711.45 | U15: 19.2 | V15: 0 | W15: 0 | X15: 95747.61 | Y15: 1606.6 | Z15: 2017.62 | AA15: 0 | AB15: 4.76 | AC15: 0 | AD15: 0 | AE15: 0 | AF15: 0 | AG15: 172829.54 | AH15: 12653.72 | AI15: 183482.61 | AJ15: 129326.6 | AK15: 0 | AL15: 108825.79 | AM15: 1.5867149 | AN15: 0 | AO15: 0 | AP15: 86603.82 | AQ15: 24384.88 | AS15: 44227 | AT15: ENERO | AU15: Positivo | AV15: 2021 | AW15: BBVA C.A. | AX15: 1.51 | AY15: 1.82
A16: 121 | B16: Bolivariana de Seguros y Reaseguros, S.A. | C16: 3.81 | D16: 0 | E16: 69.62 | F16: 0 | G16: 7416.09 | H16: 5320.42 | I16: 78064.59 | J16: 1503816.8 | K16: 504.58 | L16: 434.97 | M16: 1486.4 | N16: 0 | O16: -1346.15 | P16: -6066.13 | Q16: -287.26 | R16: -6353.39 | S16: 11673.81 | T16: 0 | U16: 0 | V16: 0 | W16: 4197.63 | X16: 7823.3 | Y16: 151.35 | Z16: 151.32 | AA16: 0 | AB16: 44.44 | AC16: 0 | AD16: 0 | AE16: 0 | AF16: 0 | AG16: 1921.36 | AH16: 69.62 | AI16: 1985.16 | AJ16: 3331.31 | AK16: 0 | AL16: 77560.01 | AM16: 154.71202 | AN16: 0 | AO16: 0 | AP16: 1070.67 | AQ16: -279.28 | AS16: 44227 | AT16: ENERO | AU16: Positivo | AV16: 2021 | AW16: BOLIVARIANA S.A. | AX16: 1.51 | AY16: 1.82
A17: 122 | B17: Capital, C.A. Seguros | C17: 44896.96 | D17: 0 | E17: 0 | F17: 0 | G17: 2379.34 | H17: 2052.63 | I17: 51870.2 | J17: 0 | K17: 2.23 | L17: 2.23 | M17: 1676.19 | N17: 0 | O17: 423.59 | P17: 42094.03 | Q17: -39983.35 | R17: 2110.68 | S17: -58.06 | T17: 0 | U17: 0 | V17: 0 | W17: 0 | X17: 0 | Y17: 48.56 | Z17: 2.39 | AA17: 0 | AB17: 7.12 | AC17: 0 | AD17: 0 | AE17: 0 | AF17: 0 | AG17: 1678.43 | AH17: 0 | AI17: 1678.19 | AJ17: 1254.6 | AK17: 0 | AL17: 51867.97 | AM17: 23260.179 | AN17: 0 | AO17: 0 | AP17: 44473.37 | AQ17: 0 | AS17: 44227 | AT17: ENERO | AU17: Positivo | AV17: 2021 | AW17: CAPITAL C.A. | AX17: 1.51 | AY17: 1.82
A18: 13 | B18: Caracas C.A., Seguros | C18: 9074282.1 | D18: 4407699 | E18: 6969072.2 | F18: 1550567.1 | G18: 2238860.6 | H18: 6040911.4 | I18: 58910597 | J18: 35432636 | K18: 21801653 | L18: 14832573 | M18: 88943.15 | N18: 11546.97 | O18: 8112638.6 | P18: -7235483.2 | Q18: -664348.87 | R18: -7899832 | S18: 13940743 | T18: 18524.55 | U18: 4162.83 | V18: 0 | W18: 80.79 | X18: 15725542 | Y18: 45691.03 | Z18: 263880.58 | AA18: 28680.33 | AB18: 380.48 | AC18: 0 | AD18: 0 | AE18: 0 | AF18: 1468934.5 | AG18: 14921517 | AH18: 6980619.2 | AI18: 21858594 | AJ18: 13745956 | AK18: 0.08 | AL18: 37108944 | AM18: 2.7021161 | AN18: 1144413.9 | AO18: 406153.2 | AP18: 4694041.5 | AQ18: 8140097 | AS18: 44227 | AT18: ENERO | AU18: Positivo | AV18: 2021 | AW18: CARACAS C.A. | AX18: 1.51 | AY18: 1.82
... A81: 91 | B81: Multinacional de Seguros C.A. | C81: 97517.07 | D81: 5265.48 | E81: 12499.41 | F81: 20248.27 | G81: 107607.59 | H81: -870541 | I81: 65655744 | J81: 12276206 | K81: 33719.1 | L81: 20773.36 | M81: 0 | N81: 429716.63 | O81: 104738.22 | P81: -140342.49 | Q81: 304208.72 | R81: 163866.23 | S81: -1034407.2 | T81: 6.48 | U81: 0 | V81: 0 | W81: 0 | X81: 38761.37 | Y81: 516.86 | Z81: 13634.63 | AA81: 514094.7 | AB81: 506226.95 | AC81: 0 | AD81: 0 | AE81: 0 | AF81: 38701.93 | AG81: 20773.36 | AH81: 442216.04 | AI81: 462958.13 | AJ81: 358219.91 | AK81: 0 | AL81: 65622025 | AM81: 1947.1381 | AN81: 20248.27 | AO81: 0 | AP81: 78693.78 | AQ81: 91180.41 | AS81: 44255 | AT81: FEBRERO | AU81: Negativo | AV81: 2021 | AW81: MULTINACIONAL C.A. | AX81: 1.8 | AY81: 1.87
A82: 73 | B82: Mundial de Seguros,C.A. | C82: 0 | D82: 0 | E82: 0 | F82: 0 | G82: 51190.02 | H82: -141044.18 | I82: 15155.21 | J82: 235329.93 | K82: 0 | L82: 0 | M82: 0 | N82: 0 | O82: -1427.87 | P82: -49762.15 | Q82: -571.15 | R82: -50333.3 | S82: -90710.89 | T82: 0.15 | U82: 0 | V82: 0 | W82: 0 | X82: 133604.58 | Y82: 1044.69 | Z82: 0.26 | AA82: 12.6 | AB82: 1.9 | AC82: 0 | AD82: 0 | AE82: 0 | AF82: 223256.17 | AG82: 0 | AH82: 0 | AI82: 0 | AJ82: 1427.87 | AK82: 0 | AL82: 15155.21 | AN82: 0 | AO82: 0 | AP82: 1427.87 | AQ82: 0 | AS82: 44255 | AT82: FEBRERO | AU82: Negativo | AV82: 2021 | AW82: MUNDIAL C.A. | AX82: 1.8 | AY82: 1.87
A83: 46 | B83: Nuevo Mundo S.A., Seguros | C83: 324434.54 | D83: 54179.16 | E83: 96847.53 | F83: 61503.31 | G83: 68332.11 | H83: 20008.78 | I83: 9197196.6 | J83: 879031.62 | K83: 502892.84 | L83: 406043.93 | M83: 31515.2 | N83: 3.14 | O83: 176974.98 | P83: -36555.02 | Q83: -4495.06 | R83: -41050.08 | S83: 61058.86 | T83: 69683.86 | U83: 0 | V83: 0 | W83: 0 | X83: 0 | Y83: 1394.53 | Z83: 796.25 | AA83: 5351.48 | AB83: 1082.74 | AC83: 0 | AD83: 0 | AE83: 0 | AF83: 0 | AG83: 437559.13 | AH83: 96850.67 | AI83: 533856.83 | AJ83: 356881.85 | AK83: 0 | AL83: 8694303.7 | AM83: 18.288581 | AN83: 34207.74 | AO83: 27295.58 | AP83: 122636.18 | AQ83: 29355.78 | AS83: 44255 | AT83: FEBRERO | AU83: Positivo | AV83: 2021 | AW83: NUEVO MUNDO S.A. | AX83: 1.8 | AY83: 1.87
A84: 51 | B84: Occidental C.A., Seguros | C84: 626179.48 | D84: 95401.68 | E84: 744816.45 | F84: 35131.95 | G84: 726438.62 | H84: 190352.1 | I84: 10376787 | J84: 11443842 | K84: 1340046.1 | L84: 595229.63 | M84: 80125.57 | N84: 8.84 | O84: 711863.31 | P84: -942656.08 | Q84: -3721.6 | R84: -946377.68 | S84: 1136729.8 | T84: 0 | U84: 0 | V84: 0 | W84: 0 | X84: 5090301.7 | Y84: 13939.29 | Z84: 17820.76 | AA84: 954063.73 | AB84: 919.13 | AC84: 0 | AD84: 0 | AE84: 0 | AF84: 2966829 | AG84: 675355.2 | AH84: 744825.29 | AI84: 1420051.5 | AJ84: 708188.16 | AK84: 0 | AL84: 9036740.6 | AM84: 7.7436043 | AN84: 22963.35 | AO84: 12168.59 | AP84: 164631.08 | AQ84: 345716.6 | AS84: 44255 | AT84: FEBRERO | AU84: Positivo | AV84: 2021 | AW84: OCCIDENTAL C.A. | AX84: 1.8 | AY84: 1.87
A85: 117 | B85: Oceánica de Seguros, C.A. | C85: 5104187.7 | D85: 3077849.4 | E85: 247085.42 | F85: 765378.64 | G85: 1402282.9 | H85: 16365.11 | I85: 6741659.5 | J85: 2892983.3 | K85: 687125.16 | L85: 440039.73 | M85: 7312407.5 | N85: 4683122.6 | O85: 4312782.9 | P85: -4454106.2 | Q85: 4514027.1 | R85: 59920.96 | S85: -43555.84 | T85: 72.82 | U85: 0 | V85: 0 | W85: 2758.59 | X85: 920456.17 | Y85: 15344.87 | Z85: 68754.31 | AA85: 20621.81 | AB85: 4647.16 | AC85: 0 | AD85: 0 | AE85: 0 | AF85: 857475.27 | AG85: 7752447.2 | AH85: 4930208 | AI85: 12681631 | AJ85: 8368848.5 | AK85: 0 | AL85: 6054534.3 | AM85: 9.8113996 | AN85: 721155.38 | AO85: 44223.27 | AP85: 3606719.7 | AQ85: 5893164.4 | AS85: 44255 | AT85: FEBRERO | AU85: Positivo | AV85: 2021 | AW85: OCEÁNICA C.A. | AX85: 1.8 | AY85: 1.87
A86: 78 | B86: Oriental de Seguros C.A. | C86: 14434.13 | D86: 0 | E86: 1.93 | F86: 2180.27 | G86: 14994.78 | H86: 29091.17 | I86: 108907.52 | J86: 107788.54 | K86: 11119.46 | L86: 11117.54 | M86: 35010.81 | N86: 0 | O86: 14123.84 | P86: -16864.76 | Q86: 4776.57 | R86: -12088.19 | S86: 41179.37 | T86: 1514.39 | U86: 3.25 | V86: 0 | W86: 0 | X86: 40696.22 | Y86: 294.02 | Z86: 735.82 | AA86: 0 | AB86: 4.55 | AC86: 0 | AD86: 0 | AE86: 0 | AF86: 0.11 | AG86: 46128.34 | AH86: 1.93 | AI86: 46119.24 | AJ86: 31995.4 | AK86: 0 | AL86: 97788.06 | AM86: 9.7943173 | AN86: 1757.48 | AO86: 422.8 | AP86: 311.07 | AQ86: 0.79 | AS86: 44255 | AT86: FEBRERO | AU86: Positivo | AV86: 2021 | AW86: ORIENTAL C.A. | AX86: 1.8 | AY86: 1.87
A87: 80 | B87: Pirámide C.A., Seguros | C87: 15906287 | D87: 6720497.5 | E87: 668038.2 | F87: 1444672.6 | G87: 3055119.6 | H87: 21120.51 | I87: 21985409 | J87: 31521345 | K87: 1014401.1 | L87: 346362.93 | M87: 9707168.3 | N87: 1.2497847e+08 | O87: 58705519 | P87: -54019522 | Q87: 55353887 | R87: 1334364.7 | S87: -1313244.2 | T87: 143.09 | U87: 0 | V87: 0 | W87: 364.41 | X87: 6868021.2 | Y87: 48560.58 | Z87: 203841.13 | AA87: 7689301.5 | AB87: 13744.74 | AC87: 0 | AD87: 0 | AE87: 0 | AF87: 226324.97 | AG87: 10053531 | AH87: 1.2564651e+08 | AI87: 1.3568234e+08 | AJ87: 76976819 | AK87: 0 | AL87: 20971007 | AM87: 21.673289 | AN87: 1335328.4 | AO87: 109344.21 | AP87: 11515618 | AQ87: 61035347 | AS87: 44255 | AT87: FEBRERO | AU87: Positivo | AV87: 2021 | AW87: PIRÁMIDE C.A. | AX87: 1.8 | AY87: 1.87
A88: 2 | B88: Previsora, C.N.A. de Seguros | C88: 370417.46 | D88: 925.32 | E88: 3504.38 | F88: 1393.81 | G88: 104071.47 | H88: 51723.05 | I88: 4966636.1 | J88: 4376953.5 | K88: 49895.95 | L88: 46391.57 | M88: 64.74 | N88: 3.19 | O88: 33534.86 | P88: 230492 | Q88: -195434.55 | R88: 35057.45 | S88: 16665.6 | T88: 13031.35 | U88: 0 | V88: 0 | W88: 4600 | X88: 6900.26 | Y88: 2113.7 | Z88: 0 | AA88: 4155.33 | AB88: 0 | AC88: 0 | AD88: 0 | AE88: 0 | AF88: 1596.98 | AG88: 46456.31 | AH88: 3507.57 | AI88: 49905.99 | AJ88: 16371.13 | AK88: 0 | AL88: 4916740.2 | AM88: 99.539865 | AN88: 1393.81 | AO88: 0 | AP88: 336803.97 | AQ88: 846.7 | AS88: 44255 | AT88: FEBRERO | AU88: Positivo | AV88: 2021 | AW88: PREVISORA C.N.A. | AX88: 1.8 | AY88: 1.87
A89: 115 | B89: Seguros Seguramiga C.A. | C89: 0.06 | D89: 0 | E89: 0 | F89: 0 | G89: 4749.53 | H89: 105753.37 | I89: 149815.77 | J89: 272647.04 | K89: 12.25 | L89: 12.25 | M89: 0 | N89: 0 | O89: -2.5 | P89: -4746.97 | Q89: 0 | R89: -4746.97 | S89: 110500.32 | T89: 4.72 | U89: 0 | V89: 0 | W89: 0 | X89: 110835.52 | Y89: 96.93 | Z89: 74.05 | AA89: 0 | AB89: 0.01 | AC89: 0 | AD89: 0 | AE89: 168.94 | AF89: 0 | AG89: 12.25 | AH89: 0 | AI89: 11.88 | AJ89: 14.38 | AK89: 0 | AL89: 149803.52 | AM89: 12229.859 | AN89: 0 | AO89: 0 | AP89: 2.56 | AQ89: 0 | AS89: 44255 | AT89: FEBRERO | AU89: Positivo | AV89: 2021 | AW89: SEGURAMIGA C.A. | AX89: 1.8 | AY89: 1.87
A90: 106 | B90: Proseguros, S.A. | C90: 102359.85 | D90: 11.47 | E90: 198.73 | F90: 21080.27 | G90: 45249.02 | H90: 79.86 | I90: 305162.97 | J90: 7770.98 | K90: 64615.99 | L90: 64417.25 | M90: 68008.86 | N90: 11.85 | O90: 68404.62 | P90: -32385.53 | Q90: 8845.77 | R90: -23539.76 | S90: 23619.64 | T90: 0.02 | U90: 0 | V90: 0 | W90: 0 | X90: 27496.05 | Y90: 918.22 | Z90: 284.46 | AA90: 840 | AB90: 317.03 | AC90: 0 | AD90: 0 | AE90: 0 | AF90: 1516.73 | AG90: 132426.12 | AH90: 210.58 | AI90: 132581.88 | AJ90: 64177.26 | AK90: 0 | AL90: 240546.98 | AM90: 4.722716 | AN90: 14967.33 | AO90: 6112.94 | AP90: 34154.49 | AQ90: 210.72 | AS90: 44255 | AT90: FEBRERO | AU90: Positivo | AV90: 2021 | AW90: PROSEGUROS S.A. | AX90: 1.8 | AY90: 1.87
A91: 118 | B91: Qualitas C.A., Seguros | C91: 1064307.5 | D91: 143154.23 | E91: 48345.46 | F91: 77692.57 | G91: 161768.39 | H91: 7387.85 | I91: 3831802.2 | J91: 836581.04 | K91: 132124.09 | L91: 83778.63 | M91: 713855.87 | N91: 444840.55 | O91: 520835.03 | P91: 160857.24 | Q91: -130918.57 | R91: 29938.67 | S91: -22550.82 | T91: 32.29 | U91: 0 | V91: 0 | W91: 2985.09 | X91: 11519.03 | Y91: 2956.33 | Z91: 1888.89 | AA91: 28642.47 | AB91: 799.46 | AC91: 0 | AD91: 0 | AE91: 2800.08 | AF91: 0.01 | AG91: 797634.5 | AH91: 493186.01 | AI91: 1290767.8 | AJ91: 769932.79 | AK91: 0 | AL91: 3699678.1 | AM91: 29.001541 | AN91: 50351.51 | AO91: 27341.06 | AP91: 771070.59 | AQ91: 370752.39 | AS91: 44255 | AT91: FEBRERO | AU91: Positivo | AV91: 2021 | AW91: QUALITAS C.A. | AX91: 1.8 | AY91: 1.87
A92: 29 | B92: Real Seguros, S.A. | C92: 1223702.3 | D92: 56628.23 | E92: 94477.01 | F92: 178884.13 | G92: 276499.3 | H92: 467778.04 | I92: 11113413 | J92: 8632313.4 | K92: 548664.36 | L92: 454187.34 | M92: 805946.28 | N92: 549404.04 | O92: 807567.89 | P92: -95877.27 | Q92: -135751.75 | R92: -231629.02 | S92: 699407.1 | T92: 468040.34 | U92: 0 | V92: 0 | W92: 0 | X92: 1296677 | Y92: 5642.84 | Z92: 8012.23 | AA92: 6446.34 | AB92: 675.03 | AC92: 0 | AD92: 0 | AE92: 0 | AF92: 1044533.8 | AG92: 1260133.6 | AH92: 643881.05 | AI92: 1896418.3 | AJ92: 1088850.4 | AK92: 0 | AL92: 10564748 | AM92: 20.255394 | AN92: 152388.99 | AO92: 26495.14 | AP92: 749172.04 | AQ92: 389665.91 | AS92: 44255 | AT92: FEBRERO | AU92: Positivo | AV92: 2021 | AW92: REAL S.A. | AX92: 1.8 | AY92: 1.87
A93: 111 | B93: Universal de Seguros C.A. | C93: 130170.09 | D93: 6564.62 | E93: 100591.56 | F93: 9698.51 | G93: 173186.59 | H93: 19013.71 | I93: 287884.95 | J93: 86041.03 | K93: 203509.16 | L93: 102917.59 | M93: 0 | N93: 0 | O93: -64564.76 | P93: 5285.13 | Q93: -7425.73 | R93: -2140.6 | S93: 21154.32 | T93: 0 | U93: 0 | V93: 0 | W93: 238.84 | X93: 43377.86 | Y93: 3525.26 | Z93: 1594.34 | AA93: 11156.6 | AB93: 112.33 | AC93: 0 | AD93: 0 | AE93: 0 | AF93: 6073.85 | AG93: 102917.59 | AH93: 100591.56 | AI93: 203482.48 | AJ93: 268047.24 | AK93: 0 | AL93: 84375.79 | AM93: 1.4146044 | AN93: 5628.02 | AO93: 4070.49 | AP93: 199453.07 | AQ93: 11282.85 | AS93: 44255 | AT93: FEBRERO | AU93: Positivo | AV93: 2021 | AW93: UNIVERSAL C.A. | AX93: 1.8 | AY93: 1.87
A94: 83 | B94: Universitas, C.A. Seguros | C94: 8119615.9 | D94: 486464.96 | E94: 5212572.8 | F94: 1379529.8 | G94: 3040701.2 | H94: 145767.19 | I94: 16470210 | J94: 1510437.7 | K94: 9849333.3 | L94: 4636760.5 | M94: 6202795.3 | N94: 0 | O94: 5502719.5 | P94: -2289799.5 | Q94: -1698357.9 | R94: -3988157.5 | S94: 4133924.6 | T94: 48438.99 | U94: 0 | V94: 0 | W94: 193436.62 | X94: 5130906.2 | Y94: 36921.12 | Z94: 111713.38 | AA94: 229256.91 | AB94: 11955.81 | AC94: 0 | AD94: 0 | AE94: 0 | AF94: 849009.99 | AG94: 10839556 | AH94: 5212572.8 | AI94: 16044185 | AJ94: 10541465 | AK94: 0 | AL94: 6620876.5 | AM94: 1.6722157 | AN94: 1149498.5 | AO94: 230031.25 | AP94: 4766682.1 | AQ94: 2636250.5 | AS94: 44255 | AT94: FEBRERO | AU94: Positivo | AV94: 2021 | AW94: UNIVERSITAS C.A. | AX94: 1.8 | AY94: 1.87
... A128: 91 | B128: Multinacional de Seguros C.A. | C128: 138628.41 | D128: 5306.44 | E128: 12015.31 | F128: 21026.67 | G128: 160984.37 | H128: -1164560.8 | I128: 65445859 | J128: 12259982 | K128: 31417.46 | L128: 18955.82 | M128: 0 | N128: 429716.63 | O128: 102436.58 | P128: -151125.65 | Q128: 304208.72 | R128: 153083.07 | S128: -1317643.8 | T128: 6.48 | U128: 0 | V128: 0 | W128: 0 | X128: 56594.47 | Y128: 822.03 | Z128: 21581.47 | AA128: 547595.17 | AB128: 759340.43 | AC128: 0 | AD128: 0 | AE128: 0 | AF128: 44905.69 | AG128: 18955.83 | AH128: 441731.94 | AI128: 460656.49 | AJ128: 358219.91 | AK128: 0 | AL128: 65414442 | AM128: 2083.1047 | AN128: 21026.67 | AO128: 0 | AP128: 121622.66 | AQ128: 90737.27 | AS128: 44286 | AT128: MARZO | AU128: Negativo | AV128: 2021 | AW128: MULTINACIONAL C.A. | AX128: 1.86 | AY128: 1.97
A129: 73 | B129: Mundial de Seguros,C.A. | C129: 0 | D129: -57637 | E129: 0 | F129: 0 | G129: 79813.35 | H129: -191248.28 | I129: 43527.11 | J129: 260345.43 | K129: 0 | L129: 0 | M129: 0 | N129: 0 | O129: -1427.87 | P129: -20748.48 | Q129: -54173.59 | R129: -74922.07 | S129: -116326.21 | T129: 0.64 | U129: 0 | V129: 0 | W129: 0 | X129: 143776.59 | Y129: 1628.84 | Z129: 0.26 | AA129: 15.8 | AB129: 2.9 | AC129: 0 | AD129: 0 | AE129: 0 | AF129: 258455.65 | AG129: 0 | AH129: 0 | AI129: 0 | AJ129: 1427.87 | AK129: 0 | AL129: 43527.11 | AN129: 0 | AO129: 0 | AP129: 1427.87 | AQ129: -57637 | AS129: 44286 | AT129: MARZO | AU129: Negativo | AV129: 2021 | AW129: MUNDIAL C.A. | AX129: 1.86 | AY129: 1.97
A130: 46 | B130: Nuevo Mundo S.A., Seguros | C130: 561503.54 | D130: 98288.61 | E130: 155016.52 | F130: 106983.7 | G130: 159146.67 | H130: 15766.02 | I130: 9160791.3 | J130: 1057551.1 | K130: 694383.55 | L130: 539365.65 | M130: 35446.82 | N130: 3.14 | O130: 372397.3 | P130: -175312.74 | Q130: -5919.83 | R130: -181232.57 | S130: 196998.58 | T130: 93289.75 | U130: 0 | V130: 0 | W130: 0 | X130: 115000 | Y130: 3247.89 | Z130: 1069.28 | AA130: 5351.48 | AB130: 1622.51 | AC130: 0 | AD130: 0 | AE130: 0 | AF130: 0 | AG130: 574812.46 | AH130: 155019.66 | AI130: 729279.15 | AJ130: 356881.85 | AK130: 0 | AL130: 8466407.8 | AM130: 13.192696 | AN130: 64031.75 | AO130: 42951.95 | AP130: 222451.84 | AQ130: 131634.21 | AS130: 44286 | AT130: MARZO | AU130: Positivo | AV130: 2021 | AW130: NUEVO MUNDO S.A. | AX130: 1.86 | AY130: 1.97
A131: 51 | B131: Occidental C.A., Seguros | C131: 866876.41 | D131: 112388.2 | E131: 1004975.3 | F131: 66702.79 | G131: 901039.41 | H131: 152661.62 | I131: 10346414 | J131: 11613606 | K131: 1639765.4 | L131: 634790.07 | M131: 154178.33 | N131: 48165.78 | O131: 1133792.3 | P131: -1347046.3 | Q131: -9295.58 | R131: -1356341.9 | S131: 1509003.5 | T131: 0 | U131: 0 | V131: 0 | W131: 0 | X131: 5554214.2 | Y131: 16536.96 | Z131: 21278.6 | AA131: 427551.82 | AB131: 1428.33 | AC131: 0 | AD131: 0 | AE131: 0 | AF131: 3578415 | AG131: 788968.39 | AH131: 1053141.1 | AI131: 1841980.5 | AJ131: 708188.16 | AK131: 0 | AL131: 8706648.4 | AM131: 6.3096916 | AN131: 39740.82 | AO131: 26961.96 | AP131: 291714.81 | AQ131: 671018.91 | AS131: 44286 | AT131: MARZO | AU131: Positivo | AV131: 2021 | AW131: OCCIDENTAL C.A. | AX131: 1.86 | AY131: 1.97
A132: 117 | B132: Oceánica de Seguros, C.A. | C132: 10748941 | D132: 6427225.1 | E132: 333318.39 | F132: 1495536 | G132: 2343393.1 | H132: 21274.65 | I132: 10438969 | J132: 5055916.7 | K132: 924513.44 | L132: 591195.05 | M132: 9796097.7 | N132: 4995029 | O132: 7345767.9 | P132: -6862981.2 | Q132: 7319589.1 | R132: 456607.85 | S132: -435333.21 | T132: 429.03 | U132: 0 | V132: 0 | W132: 10883.14 | X132: 1578387.7 | Y132: 27356.74 | Z132: 108843.58 | AA132: 1008364.8 | AB132: 8607.13 | AC132: 0 | AD132: 0 | AE132: 0 | AF132: 871860.86 | AG132: 10387293 | AH132: 5328347.4 | AI132: 15714616 | AJ132: 8368848.5 | AK132: 0 | AL132: 9514455.2 | AM132: 11.291311 | AN132: 1440752.3 | AO132: 54783.74 | AP132: 6616627.3 | AQ132: 9640679.4 | AS132: 44286 | AT132: MARZO | AU132: Positivo | AV132: 2021 | AW132: OCEÁNICA C.A. | AX132: 1.86 | AY132: 1.97
A133: 78 | B133: Oriental de Seguros C.A. | C133: 27589.64 | D133: 0 | E133: 2.05 | F133: 4049.77 | G133: 30892.06 | H133: 24231.26 | I133: 110283.23 | J133: 115535.39 | K133: 14176.27 | L133: 14174.22 | M133: 34728.53 | N133: 0 | O133: 16898.37 | P133: -24250.56 | Q133: 1539.71 | R133: -22710.85 | S133: 46942.1 | T133: 1531.1 | U133: 9.43 | V133: 0 | W133: 0 | X133: 46987.39 | Y133: 600.77 | Z133: 978.11 | AA133: 0 | AB133: 6.83 | AC133: 0 | AD133: 0 | AE133: 0 | AF133: 0.11 | AG133: 48902.76 | AH133: 2.05 | AI133: 48893.77 | AJ133: 31995.4 | AK133: 0 | AL133: 96106.96 | AM133: 7.7794251 | AN133: 3342.42 | AO133: 707.35 | AP133: 10692.16 | AQ133: 0.91 | AS133: 44286 | AT133: MARZO | AU133: Positivo | AV133: 2021 | AW133: ORIENTAL C.A. | AX133: 1.86 | AY133: 1.97
A134: 80 | B134: Pirámide C.A., Seguros | C134: 24783582 | D134: 12526081 | E134: 800379.82 | F134: 2469511 | G134: 4854810.9 | H134: 27456.67 | I134: 24331972 | J134: 27351857 | K134: 1163960.3 | L134: 363580.48 | M134: 12097967 | N134: 1.349624e+08 | O134: 71229802 | P134: -66296623 | Q134: 67520139 | R134: 1223515.9 | S134: -1196059.2 | T134: 2062.85 | U134: 0 | V134: 0 | W134: 127088.94 | X134: 7612673.9 | Y134: 68379.25 | Z134: 425278.65 | AA134: 8145873.1 | AB134: 22532.74 | AC134: 0 | AD134: 0 | AE134: 0 | AF134: 275821.18 | AG134: 12461548 | AH134: 1.3576278e+08 | AI134: 1.4820662e+08 | AJ134: 76976819 | AK134: 0 | AL134: 23168012 | AM134: 20.904469 | AN134: 2233558.5 | AO134: 235952.47 | AP134: 17984896 | AQ134: 76957197 | AS134: 44286 | AT134: MARZO | AU134: Positivo | AV134: 2021 | AW134: PIRÁMIDE C.A. | AX134: 1.86 | AY134: 1.97
A135: 2 | B135: Previsora, C.N.A. de Seguros | C135: 474233.33 | D135: 4744.66 | E135: 3504.38 | F135: 1393.81 | G135: 217411.82 | H135: 2811.94 | I135: 4953871.7 | J135: 4376953.5 | K135: 49895.95 | L135: 46391.57 | M135: 64.74 | N135: 3.19 | O135: 33534.86 | P135: 217148.18 | Q135: -248472.36 | R135: -31324.18 | S135: 34136.13 | T135: 13031.35 | U135: 0 | V135: 0 | W135: 9138.67 | X135: 23869.62 | Y135: 4426.77 | Z135: 0 | AA135: 5879.76 | AB135: 0 | AC135: 0 | AD135: 0 | AE135: 0 | AF135: 1596.98 | AG135: 46456.31 | AH135: 3507.57 | AI135: 49905.99 | AJ135: 16371.13 | AK135: 0 | AL135: 4903975.8 | AM135: 99.284044 | AN135: 1393.81 | AO135: 0 | AP135: 440619.84 | AQ135: 4666.04 | AS135: 44286 | AT135: MARZO | AU135: Positivo | AV135: 2021 | AW135: PREVISORA C.N.A. | AX135: 1.86 | AY135: 1.97
A136: 115 | B136: Seguros Seguramiga C.A. | C136: 39.56 | D136: 0 | E136: 0 | F136: 0 | G136: 11449.54 | H136: 113672.77 | I136: 146047.5 | J136: 287621.67 | K136: 46.86 | L136: 46.87 | M136: 0 | N136: 0 | O136: 32.12 | P136: -11442.1 | Q136: 0 | R136: -11442.1 | S136: 125114.85 | T136: 6.96 | U136: 0 | V136: 0 | W136: 0 | X136: 125807.96 | Y136: 233.66 | Z136: 188.91 | AA136: 0 | AB136: 0.01 | AC136: 0 | AD136: 0 | AE136: 277.47 | AF136: 0 | AG136: 46.87 | AH136: 0 | AI136: 46.5 | AJ136: 14.38 | AK136: 0 | AL136: 146000.64 | AM136: 3116.6773 | AN136: 0 | AO136: 0 | AP136: 7.44 | AQ136: 0 | AS136: 44286 | AT136: MARZO | AU136: Positivo | AV136: 2021 | AW136: SEGURAMIGA C.A. | AX136: 1.86 | AY136: 1.97
A137: 106 | B137: Proseguros, S.A. | C137: 198959.66 | D137: 11.47 | E137: 452.61 | F137: 57566.59 | G137: 76170.01 | H137: 89.39 | I137: 314954.36 | J137: 7289.77 | K137: 99671.31 | L137: 99300.61 | M137: 96294.57 | N137: 20.86 | O137: 131754.66 | P137: -66543.07 | Q137: 35210.97 | R137: -31332.1 | S137: 31421.5 | T137: 0.03 | U137: 0 | V137: 0 | W137: 0 | X137: 38349.41 | Y137: 1546.13 | Z137: 521.21 | AA137: 1383 | AB137: 921.17 | AC137: 0 | AD137: 0 | AE137: 0 | AF137: 2556.41 | AG137: 195513.27 | AH137: 473.47 | AI137: 195931.92 | AJ137: 64177.26 | AK137: 0 | AL137: 215283.05 | AM137: 3.15993 | AN137: 29421.14 | AO137: 28145.46 | AP137: 67667.14 | AQ137: 473.61 | AS137: 44286 | AT137: MARZO | AU137: Positivo | AV137: 2021 | AW137: PROSEGUROS S.A. | AX137: 1.86 | AY137: 1.97
A138: 118 | B138: Qualitas C.A., Seguros | C138: 2191452 | D138: 358884.36 | E138: 98312.28 | F138: 132578.34 | G138: 373946.83 | H138: 7437.79 | I138: 3826913.6 | J138: 1204807.7 | K138: 318754.41 | L138: 220442.13 | M138: 1097929.9 | N138: 622319.42 | O138: 1269018.3 | P138: 57024.14 | Q138: -58395.94 | R138: -1371.8 | S138: 8809.58 | T138: 49.35 | U138: 0 | V138: 0 | W138: 2985.09 | X138: 58062.51 | Y138: 5979.27 | Z138: 8743.03 | AA138: 31555.22 | AB138: 1232.65 | AC138: 0 | AD138: 0 | AE138: 4775.69 | AF138: 1.5 | AG138: 1318372 | AH138: 720631.7 | AI138: 2038951.1 | AJ138: 769932.79 | AK138: 0 | AL138: 3508159.2 | AM138: 12.005837 | AN138: 85394.31 | AO138: 47184.04 | AP138: 1377477.5 | AQ138: 813928.21 | AS138: 44286 | AT138: MARZO | AU138: Positivo | AV138: 2021 | AW138: QUALITAS C.A. | AX138: 1.86 | AY138: 1.97
A139: 29 | B139: Real Seguros, S.A. | C139: 3722685.8 | D139: 364663.57 | E139: 55634.7 | F139: 411802.09 | G139: 600262.6 | H139: 422156.9 | I139: 11178966 | J139: 6716069 | K139: 664618.82 | L139: 608984.12 | M139: 2126292.4 | N139: 260121.34 | O139: 1954585.8 | P139: 391371.72 | Q139: -823204.48 | R139: -431832.76 | S139: 853989.67 | T139: 546760.6 | U139: 0 | V139: 0 | W139: 0 | X139: 1475098.5 | Y139: 12181.42 | Z139: 13619.25 | AA139: 306.73 | AB139: 1022.66 | AC139: 0 | AD139: 0 | AE139: 0 | AF139: 1140739.4 | AG139: 2735276.5 | AH139: 315756.04 | AI139: 3043436.2 | AJ139: 1088850.4 | AK139: 0 | AL139: 10514347 | AM139: 16.820116 | AN139: 280631.31 | AO139: 131170.77 | AP139: 1773012.6 | AQ139: 369576.24 | AS139: 44286 | AT139: MARZO | AU139: Positivo | AV139: 2021 | AW139: REAL S.A. | AX139: 1.86 | AY139: 1.97
...

Sheet Cuadro_1
B1: REPÚBLICA BOLIVARIANA DE VENEZUELA
B2: MINISTERIO DEL PODER POPULAR DE ECONOMíA Y FINANZAS
B3: SUPERINTENDENCIA DE LA ACTIVIDAD ASEGURADORA
B4: DIRECCIÓN ACTUARIAL / ÁREA DE INVESTIGACIÓN, TRABAJOS ESPECIALES Y ESTADÍSTICAS
B6: INFORMACIÓN FINANCIERA ANALÍTICA MENSUAL DEL MERCADO ASEGURADOR VENEZOLANO
B7: ="ACUMULADA A"&" "&UPPER(J8)&" DE "&L8 -> ACUMULADA A AGOSTO DE 2025
B8: CUADRO DE RESULTADOS | I8: Mes | J8: Agosto | K8: Año | L8: 2025
B9: (En Miles de Bs.)
B10: # | C10: Empresas de Seguros | D10: Resultado Técnico Bruto (1) | E10: Resultado del Reaseguro Cedido (2) | F10: Resultado Técnico Neto (3) = (1) + (2) | G10: Resultado de la Gestión General (4) | H10: Saldo de Operaciones (5) = (3) + (4)
C11: Primas Netas Cobradas
B13: 1 | C13: Adriática de Seguros, C.A. | D13: =SUMIFS(IFM[[ResultadoTecnicoBruto]:[ResultadoTecnicoBruto]],IFM[[Nombre Empresa]:[Nombre Empresa]],$C13,IFM[[MES]:[MES]],$J$8,IFM[[AÑO]:[AÑO]],$L$8)/1000 -> 0 | E13: =SUMIFS(IFM[[ResultadodelReaseguroCedido]:[ResultadodelReaseguroCedido]],IFM[[Nombre Empresa]:[Nombre Empresa]],$C13,IFM[[MES]:[MES]],$J$8,IFM[[AÑO]:[AÑO]],$L$8)/1000 -> 0 | F13: =+D13+E13 -> 0 | G13: =SUMIFS(IFM[[ResultadodeGestionGeneral]:[ResultadodeGestionGeneral]],IFM[[Nombre Empresa]:[Nombre Empresa]],$C13,IFM[[MES]:[MES]],$J$8,IFM[[AÑO]:[AÑO]],$L$8)/1000 -> 0 | H13: =+F13+G13 -> 0
B14: 2 | C14: Altamira C.A., Seguros | D14: =SUMIFS(IFM[[ResultadoTecnicoBruto]:[ResultadoTecnicoBruto]],IFM[[Nombre Empresa]:[Nombre Empresa]],$C14,IFM[[MES]:[MES]],$J$8,IFM[[AÑO]:[AÑO]],$L$8)/1000 -> 99837.316 | E14: =SUMIFS(IFM[[ResultadodelReaseguroCedido]:[ResultadodelReaseguroCedido]],IFM[[Nombre Empresa]:[Nombre Empresa]],$C14,IFM[[MES]:[MES]],$J$8,IFM[[AÑO]:[AÑO]],$L$8)/1000 -> -37905.508 | F14: =+D14+E14 -> 61931.808 | G14: =SUMIFS(IFM[[ResultadodeGestionGeneral]:[ResultadodeGestionGeneral]],IFM[[Nombre Empresa]:[Nombre Empresa]],$C14,IFM[[MES]:[MES]],$J$8,IFM[[AÑO]:[AÑO]],$L$8)/1000 -> -61335.808 | H14: =+F14+G14 -> 595.99998
B15: 3 | C15: American International, C.A. de Seguros | D15: =SUMIFS(IFM[[ResultadoTecnicoBruto]:[ResultadoTecnicoBruto]],IFM[[Nombre Empresa]:[Nombre Empresa]],$C15,IFM[[MES]:[MES]],$J$8,IFM[[AÑO]:[AÑO]],$L$8)/1000 -> -76031.499 | E15: =SUMIFS(IFM[[ResultadodelReaseguroCedido]:[ResultadodelReaseguroCedido]],IFM[[Nombre Empresa]:[Nombre Empresa]],$C15,IFM[[MES]:[MES]],$J$8,IFM[[AÑO]:[AÑO]],$L$8)/1000 -> 6946.8243 | F15: =+D15+E15 -> -69084.674 | G15: =SUMIFS(IFM[[ResultadodeGestionGeneral]:[ResultadodeGestionGeneral]],IFM[[Nombre Empresa]:[Nombre Empresa]],$C15,IFM[[MES]:[MES]],$J$8,IFM[[AÑO]:[AÑO]],$L$8)/1000 -> 4963.4637 | H15: =+F15+G15 -> -64121.211
B16: 4 | C16: Andes C.A., Seguros | D16: =SUMIFS(IFM[[ResultadoTecnicoBruto]:[ResultadoTecnicoBruto]],IFM[[Nombre Empresa]:[Nombre Empresa]],$C16,IFM[[MES]:[MES]],$J$8,IFM[[AÑO]:[AÑO]],$L$8)/1000 -> -41158.738 | E16: =SUMIFS(IFM[[ResultadodelReaseguroCedido]:[ResultadodelReaseguroCedido]],IFM[[Nombre Empresa]:[Nombre Empresa]],$C16,IFM[[MES]:[MES]],$J$8,IFM[[AÑO]:[AÑO]],$L$8)/1000 -> -718.88787 | F16: =+D16+E16 -> -41877.625 | G16: =SUMIFS(IFM[[ResultadodeGestionGeneral]:[ResultadodeGestionGeneral]],IFM[[Nombre Empresa]:[Nombre Empresa]],$C16,IFM[[MES]:[MES]],$J$8,IFM[[AÑO]:[AÑO]],$L$8)/1000 -> 3965.5963 | H16: =+F16+G16 -> -37912.029
B17: 5 | C17: Aseguradora Nacional Unida Uniseguros, S.A. | D17: =SUMIFS(IFM[[ResultadoTecnicoBruto]:[ResultadoTecnicoBruto]],IFM[[Nombre Empresa]:[Nombre Empresa]],$C17,IFM[[MES]:[MES]],$J$8,IFM[[AÑO]:[AÑO]],$L$8)/1000 -> -15905.946 | E17: =SUMIFS(IFM[[ResultadodelReaseguroCedido]:[ResultadodelReaseguroCedido]],IFM[[Nombre Empresa]:[Nombre Empresa]],$C17,IFM[[MES]:[MES]],$J$8,IFM[[AÑO]:[AÑO]],$L$8)/1000 -> -17448.406 | F17: =+D17+E17 -> -33354.352 | G17: =SUMIFS(IFM[[ResultadodeGestionGeneral]:[ResultadodeGestionGeneral]],IFM[[Nombre Empresa]:[Nombre Empresa]],$C17,IFM[[MES]:[MES]],$J$8,IFM[[AÑO]:[AÑO]],$L$8)/1000 -> 33800.622 | H17: =+F17+G17 -> 446.26961
B18: 6 | C18: Atrio Seguros S.A. | D18: =SUMIFS(IFM[[ResultadoTecnicoBruto]:[ResultadoTecnicoBruto]],IFM[[Nombre Empresa]:[Nombre Empresa]],$C18,IFM[[MES]:[MES]],$J$8,IFM[[AÑO]:[AÑO]],$L$8)/1000 -> -1152.9353 | E18: =SUMIFS(IFM[[ResultadodelReaseguroCedido]:[ResultadodelReaseguroCedido]],IFM[[Nombre Empresa]:[Nombre Empresa]],$C18,IFM[[MES]:[MES]],$J$8,IFM[[AÑO]:[AÑO]],$L$8)/1000 -> 9106.4357 | F18: =+D18+E18 -> 7953.5004 | G18: =SUMIFS(IFM[[ResultadodeGestionGeneral]:[ResultadodeGestionGeneral]],IFM[[Nombre Empresa]:[Nombre Empresa]],$C18,IFM[[MES]:[MES]],$J$8,IFM[[AÑO]:[AÑO]],$L$8)/1000 -> -7422.1486 | H18: =+F18+G18 -> 531.35183
B19: 7 | C19: Ávila C.A., de Seguros | D19: =SUMIFS(IFM[[ResultadoTecnicoBruto]:[ResultadoTecnicoBruto]],IFM[[Nombre Empresa]:[Nombre Empresa]],$C19,IFM[[MES]:[MES]],$J$8,IFM[[AÑO]:[AÑO]],$L$8)/1000 -> 0 | E19: =SUMIFS(IFM[[ResultadodelReaseguroCedido]:[ResultadodelReaseguroCedido]],IFM[[Nombre Empresa]:[Nombre Empresa]],$C19,IFM[[MES]:[MES]],$J$8,IFM[[AÑO]:[AÑO]],$L$8)/1000 -> 0 | F19: =+D19+E19 -> 0 | G19: =SUMIFS(IFM[[ResultadodeGestionGeneral]:[ResultadodeGestionGeneral]],IFM[[Nombre Empresa]:[Nombre Empresa]],$C19,IFM[[MES]:[MES]],$J$8,IFM[[AÑO]:[AÑO]],$L$8)/1000 -> 0 | H19: =+F19+G19 -> 0
B20: 8 | C20: Banesco Seguros C.A. | D20: =SUMIFS(IFM[[ResultadoTecnicoBruto]:[ResultadoTecnicoBruto]],IFM[[Nombre Empresa]:[Nombre Empresa]],$C20,IFM[[MES]:[MES]],$J$8,IFM[[AÑO]:[AÑO]],$L$8)/1000 -> 198086.65 | E20: =SUMIFS(IFM[[ResultadodelReaseguroCedido]:[ResultadodelReaseguroCedido]],IFM[[Nombre Empresa]:[Nombre Empresa]],$C20,IFM[[MES]:[MES]],$J$8,IFM[[AÑO]:[AÑO]],$L$8)/1000 -> -104975.64 | F20: =+D20+E20 -> 93111.014 | G20: =SUMIFS(IFM[[ResultadodeGestionGeneral]:[ResultadodeGestionGeneral]],IFM[[Nombre Empresa]:[Nombre Empresa]],$C20,IFM[[MES]:[MES]],$J$8,IFM[[AÑO]:[AÑO]],$L$8)/1000 -> 769269.41 | H20: =+F20+G20 -> 862380.42
B21: 9 | C21: BBVA Seguros,C.A. | D21: =SUMIFS(IFM[[ResultadoTecnicoBruto]:[ResultadoTecnicoBruto]],IFM[[Nombre Empresa]:[Nombre Empresa]],$C21,IFM[[MES]:[MES]],$J$8,IFM[[AÑO]:[AÑO]],$L$8)/1000 -> -9339.3269 | E21: =SUMIFS(IFM[[ResultadodelReaseguroCedido]:[ResultadodelReaseguroCedido]],IFM[[Nombre Empresa]:[Nombre Empresa]],$C21,IFM[[MES]:[MES]],$J$8,IFM[[AÑO]:[AÑO]],$L$8)/1000 -> -158.75959 | F21: =+D21+E21 -> -9498.0865 | G21: =SUMIFS(IFM[[ResultadodeGestionGeneral]:[ResultadodeGestionGeneral]],IFM[[Nombre Empresa]:[Nombre Empresa]],$C21,IFM[[MES]:[MES]],$J$8,IFM[[AÑO]:[AÑO]],$L$8)/1000 -> 298920.74 | H21: =+F21+G21 -> 289422.65
B22: 10 | C22: Bolivariana de Seguros y Reaseguros, S.A. | D22: =SUMIFS(IFM[[ResultadoTecnicoBruto]:[ResultadoTecnicoBruto]],IFM[[Nombre Empresa]:[Nombre Empresa]],$C22,IFM[[MES]:[MES]],$J$8,IFM[[AÑO]:[AÑO]],$L$8)/1000 -> 1182.1549 | E22: =SUMIFS(IFM[[ResultadodelReaseguroCedido]:[ResultadodelReaseguroCedido]],IFM[[Nombre Empresa]:[Nombre Empresa]],$C22,IFM[[MES]:[MES]],$J$8,IFM[[AÑO]:[AÑO]],$L$8)/1000 -> -1271.4396 | F22: =+D22+E22 -> -89.28468 | G22: =SUMIFS(IFM[[ResultadodeGestionGeneral]:[ResultadodeGestionGeneral]],IFM[[Nombre Empresa]:[Nombre Empresa]],$C22,IFM[[MES]:[MES]],$J$8,IFM[[AÑO]:[AÑO]],$L$8)/1000 -> 2492.5392 | H22: =+F22+G22 -> 2403.2545
B23: 11 | C23: Capital, C.A. Seguros | D23: =SUMIFS(IFM[[ResultadoTecnicoBruto]:[ResultadoTecnicoBruto]],IFM[[Nombre Empresa]:[Nombre Empresa]],$C23,IFM[[MES]:[MES]],$J$8,IFM[[AÑO]:[AÑO]],$L$8)/1000 -> 1191697.9 | E23: =SUMIFS(IFM[[ResultadodelReaseguroCedido]:[ResultadodelReaseguroCedido]],IFM[[Nombre Empresa]:[Nombre Empresa]],$C23,IFM[[MES]:[MES]],$J$8,IFM[[AÑO]:[AÑO]],$L$8)/1000 -> -1190020.6 | F23: =+D23+E23 -> 1677.2486 | G23: =SUMIFS(IFM[[ResultadodeGestionGeneral]:[ResultadodeGestionGeneral]],IFM[[Nombre Empresa]:[Nombre Empresa]],$C23,IFM[[MES]:[MES]],$J$8,IFM[[AÑO]:[AÑO]],$L$8)/1000 -> 1801.3056 | H23: =+F23+G23 -> 3478.5542
B24: 12 | C24: Carabobo C.A., Seguros | D24: =SUMIFS(IFM[[ResultadoTecnicoBruto]:[ResultadoTecnicoBruto]],IFM[[Nombre Empresa]:[Nombre Empresa]],$C24,IFM[[MES]:[MES]],$J$8,IFM[[AÑO]:[AÑO]],$L$8)/1000 -> 0 | E24: =SUMIFS(IFM[[ResultadodelReaseguroCedido]:[ResultadodelReaseguroCedido]],IFM[[Nombre Empresa]:[Nombre Empresa]],$C24,IFM[[MES]:[MES]],$J$8,IFM[[AÑO]:[AÑO]],$L$8)/1000 -> 0 | F24: =+D24+E24 -> 0 | G24: =SUMIFS(IFM[[ResultadodeGestionGeneral]:[ResultadodeGestionGeneral]],IFM[[Nombre Empresa]:[Nombre Empresa]],$C24,IFM[[MES]:[MES]],$J$8,IFM[[AÑO]:[AÑO]],$L$8)/1000 -> 0 | H24: =+F24+G24 -> 0
... B63: 51 | C63: Zuma Seguros, C.A. | D63: =SUMIFS(IFM[[ResultadoTecnicoBruto]:[ResultadoTecnicoBruto]],IFM[[Nombre Empresa]:[Nombre Empresa]],$C63,IFM[[MES]:[MES]],$J$8,IFM[[AÑO]:[AÑO]],$L$8)/1000 -> -48686.512 | E63: =SUMIFS(IFM[[ResultadodelReaseguroCedido]:[ResultadodelReaseguroCedido]],IFM[[Nombre Empresa]:[Nombre Empresa]],$C63,IFM[[MES]:[MES]],$J$8,IFM[[AÑO]:[AÑO]],$L$8)/1000 -> -3438.8231 | F63: =+D63+E63 -> -52125.336 | G63: =SUMIFS(IFM[[ResultadodeGestionGeneral]:[ResultadodeGestionGeneral]],IFM[[Nombre Empresa]:[Nombre Empresa]],$C63,IFM[[MES]:[MES]],$J$8,IFM[[AÑO]:[AÑO]],$L$8)/1000 -> 14232.579 | H63: =+F63+G63 -> -37892.757
C64: TOTAL (En Miles de Bs.) | D64: =SUM(D13:D63) -> -2086969.9 | E64: =SUM(E13:E63) -> -2797256.3 | F64: =SUM(F13:F63) -> -4884226.3 | G64: =SUM(G13:G63) -> 7350269.8 | H64: =SUM(H13:H63) -> 2466043.5
C66: Fuente: (SEFA) Estados Financieros Analíticos Mensuales. Empresas de Seguros. | H66: Actualizado: 09/07/2025
C67: 1/ A la fecha han consignado los estados financieros analiticos 43 empresas de seguros. 2/ Faltan por procesar los estados financieros analiticos las siguientes empresas: Adriática de Seguros, C.A., Ávila de Seguros C.A., Bolivariana de Seguros y Reaseguros, S.A., Seguros Guayana, Multinacional de Seguros C.A., Interbank Seguros S.A, La Regional C.A., y Seguros Carabobo C.A.
C69: (1) Es el proveniente de la operación técnica del seguro, sin considerar el resultado del reaseguro cedido ni las operaciones de la gestión financiera y resulta de la diferencia entre todos los ingresos de carácter técnico y los egresos por este mismo concepto, sin contemplar las cuentas del reaseguro cedido. Si el resultado es negativo, existe pérdida técnica bruta; caso contrario, existirá utilidad técnica bruta. (2) Es el proveniente de las operaciones de reaseguro cedido efectuadas por la empresa aseguradora y resulta de la diferencia entre los ingresos por reaseguro cedido y los egresos por este mismo concepto. Si los egresos de la empresa por reaseguro cedido son mayores que sus respectivos ingresos, el resultado tendrá saldo negativo; caso contrario el resultado tendrá saldo positivo. (3) Es el proveniente del ejercicio de la actividad aseguradora propiamente dicha, considerando el resultado del reaseguro cedido pero sin incluir las operaciones de la gestión financiera. Resulta de la diferencia entre todos los ingresos de carácter técnico y los egresos por este mismo concepto, incluyendo las operaciones del reaseguro cedido. Constituye también la suma entre el Resultado Técnico Bruto y el Resultado del Reaseguro Cedido. Si el resultado es negativo, existe pérdida técnica neta; caso contrario, existirá utilidad técnica neta. (4) Es el proveniente de las operaciones de la gestión financiera de la empresa aseguradora y resulta de la diferencia entre los ingresos de la gestión general y los egresos por este mismo concepto. Si los ingresos de la empresa por gestión general son menores que sus respectivos egresos, existirá pérdida financiera; caso contrario, existirá utilidad financiera. (5) Es el saldo positivo o negativo que resulta de todas las operaciones de la empresa de seguros al final del periodo evaluado. Resulta de sumar el Resultado Técnico Neto y el Resultado de la Gestión General, obteniéndose el Saldo de Operaciones Positivo o Negativo (Utilidad o Pérdida) de la empresa. Se le llama Resultado del Ejercicio toda vez que refleja el resultado de las operaciones de la empresa al cierre de cada mes del año en estudio.
C71: INFORMACIÓN PRELIMINAR NO AUDITADA POR LA SUPERINTENDENCIA DE LA ACTIVIDAD ASEGURADORA

Sheet Cuadro_2
B1: REPÚBLICA BOLIVARIANA DE VENEZUELA
B2: MINISTERIO DEL PODER POPULAR DE ECONOMíA Y FINANZAS
B3: SUPERINTENDENCIA DE LA ACTIVIDAD ASEGURADORA
B4: DIRECCIÓN ACTUARIAL / ÁREA DE INVESTIGACIÓN, TRABAJOS ESPECIALES Y ESTADÍSTICAS
B6: RESUMEN DE LA INFORMACIÓN FINANCIERA ANALÍTICA MENSUAL DEL MERCADO ASEGURADOR VENEZOLANO
B7: =+Cuadro_1!B7 -> ACUMULADA A AGOSTO DE 2025
B8: (En Miles de Bs.)
B9: # | C9: Empresas de Seguros | D9: Primas Netas Cobradas (1) | E9: Siniestros Pagados (Netos de Salvamento) (2) | F9: Reservas para Prestaciones y Siniestros Pendientes Brutas (3) | G9: Reservas para Prestaciones y Siniestros Pendientes (Netas de Reaseguradores Inscritos) (4) | H9: Siniestros Totales ( 2 + 3 ) (5) | I9: Comisiones (6) | J9: Gastos de Adquisición (7) | K9: Gastos de Administración (8)
A10: =+D10 -> 0 | B10: 1 | C10: Adriática de Seguros, C.A. | D10: =SUMIFS(IFM[[PrimasNetasCobradas]:[PrimasNetasCobradas]],IFM[[Nombre Empresa]:[Nombre Empresa]],$C10,IFM[[MES]:[MES]],Cuadro_1!$J$8,IFM[[AÑO]:[AÑO]],Cuadro_1!$L$8)/1000 -> 0 | E10: =SUMIFS(IFM[[SiniestrosPagados_NetosdeSalvamento]:[SiniestrosPagados_NetosdeSalvamento]],IFM[[Nombre Empresa]:[Nombre Empresa]],$C10,IFM[[MES]:[MES]],Cuadro_1!$J$8,IFM[[AÑO]:[AÑO]],Cuadro_1!$L$8)/1000 -> 0 | F10: =SUMIFS(IFM[[ReservasdeSiniestrosPendientesBrutas]:[ReservasdeSiniestrosPendientesBrutas]],IFM[[Nombre Empresa]:[Nombre Empresa]],$C10,IFM[[MES]:[MES]],Cuadro_1!$J$8,IFM[[AÑO]:[AÑO]],Cuadro_1!$L$8)/1000 -> 0 | G10: =SUMIFS(IFM[[SiniestrosPendientes]:[SiniestrosPendientes]],IFM[[Nombre Empresa]:[Nombre Empresa]],$C10,IFM[[MES]:[MES]],Cuadro_1!$J$8,IFM[[AÑO]:[AÑO]],Cuadro_1!$L$8)/1000 -> 0 | H10: =+E10+F10 -> 0 | I10: =SUMIFS(IFM[[Comisiones]:[Comisiones]],IFM[[Nombre Empresa]:[Nombre Empresa]],$C10,IFM[[MES]:[MES]],Cuadro_1!$J$8,IFM[[AÑO]:[AÑO]],Cuadro_1!$L$8)/1000 -> 0 | J10: =SUMIFS(IFM[[GastosdeAdquision]:[GastosdeAdquision]],IFM[[Nombre Empresa]:[Nombre Empresa]],$C10,IFM[[MES]:[MES]],Cuadro_1!$J$8,IFM[[AÑO]:[AÑO]],Cuadro_1!$L$8)/1000 -> 0 | K10: =SUMIFS(IFM[[Gastosdeadministracion]:[Gastosdeadministracion]],IFM[[Nombre Empresa]:[Nombre Empresa]],$C10,IFM[[MES]:[MES]],Cuadro_1!$J$8,IFM[[AÑO]:[AÑO]],Cuadro_1!$L$8)/1000 -> 0
A11: =+D11 -> 935942.49 | B11: 2 | C11: Altamira C.A., Seguros | D11: =SUMIFS(IFM[[PrimasNetasCobradas]:[PrimasNetasCobradas]],IFM[[Nombre Empresa]:[Nombre Empresa]],$C11,IFM[[MES]:[MES]],Cuadro_1!$J$8,IFM[[AÑO]:[AÑO]],Cuadro_1!$L$8)/1000 -> 935942.49 | E11: =SUMIFS(IFM[[SiniestrosPagados_NetosdeSalvamento]:[SiniestrosPagados_NetosdeSalvamento]],IFM[[Nombre Empresa]:[Nombre Empresa]],$C11,IFM[[MES]:[MES]],Cuadro_1!$J$8,IFM[[AÑO]:[AÑO]],Cuadro_1!$L$8)/1000 -> 188094.14 | F11: =SUMIFS(IFM[[ReservasdeSiniestrosPendientesBrutas]:[ReservasdeSiniestrosPendientesBrutas]],IFM[[Nombre Empresa]:[Nombre Empresa]],$C11,IFM[[MES]:[MES]],Cuadro_1!$J$8,IFM[[AÑO]:[AÑO]],Cuadro_1!$L$8)/1000 -> 273280.78 | G11: =SUMIFS(IFM[[SiniestrosPendientes]:[SiniestrosPendientes]],IFM[[Nombre Empresa]:[Nombre Empresa]],$C11,IFM[[MES]:[MES]],Cuadro_1!$J$8,IFM[[AÑO]:[AÑO]],Cuadro_1!$L$8)/1000 -> 50745.732 | H11: =+E11+F11 -> 461374.92 | I11: =SUMIFS(IFM[[Comisiones]:[Comisiones]],IFM[[Nombre Empresa]:[Nombre Empresa]],$C11,IFM[[MES]:[MES]],Cuadro_1!$J$8,IFM[[AÑO]:[AÑO]],Cuadro_1!$L$8)/1000 -> 44119.99 | J11: =SUMIFS(IFM[[GastosdeAdquision]:[GastosdeAdquision]],IFM[[Nombre Empresa]:[Nombre Empresa]],$C11,IFM[[MES]:[MES]],Cuadro_1!$J$8,IFM[[AÑO]:[AÑO]],Cuadro_1!$L$8)/1000 -> 94248.242 | K11: =SUMIFS(IFM[[Gastosdeadministracion]:[Gastosdeadministracion]],IFM[[Nombre Empresa]:[Nombre Empresa]],$C11,IFM[[MES]:[MES]],Cuadro_1!$J$8,IFM[[AÑO]:[AÑO]],Cuadro_1!$L$8)/1000 -> 350655.41
A12: =+D12 -> 18956.308 | B12: 3 | C12: American International, C.A. de Seguros | D12: =SUMIFS(IFM[[PrimasNetasCobradas]:[PrimasNetasCobradas]],IFM[[Nombre Empresa]:[Nombre Empresa]],$C12,IFM[[MES]:[MES]],Cuadro_1!$J$8,IFM[[AÑO]:[AÑO]],Cuadro_1!$L$8)/1000 -> 18956.308 | E12: =SUMIFS(IFM[[SiniestrosPagados_NetosdeSalvamento]:[SiniestrosPagados_NetosdeSalvamento]],IFM[[Nombre Empresa]:[Nombre Empresa]],$C12,IFM[[MES]:[MES]],Cuadro_1!$J$8,IFM[[AÑO]:[AÑO]],Cuadro_1!$L$8)/1000 -> 27305.047 | F12: =SUMIFS(IFM[[ReservasdeSiniestrosPendientesBrutas]:[ReservasdeSiniestrosPendientesBrutas]],IFM[[Nombre Empresa]:[Nombre Empresa]],$C12,IFM[[MES]:[MES]],Cuadro_1!$J$8,IFM[[AÑO]:[AÑO]],Cuadro_1!$L$8)/1000 -> 2728.2512 | G12: =SUMIFS(IFM[[SiniestrosPendientes]:[SiniestrosPendientes]],IFM[[Nombre Empresa]:[Nombre Empresa]],$C12,IFM[[MES]:[MES]],Cuadro_1!$J$8,IFM[[AÑO]:[AÑO]],Cuadro_1!$L$8)/1000 -> 0.64086 | H12: =+E12+F12 -> 30033.298 | I12: =SUMIFS(IFM[[Comisiones]:[Comisiones]],IFM[[Nombre Empresa]:[Nombre Empresa]],$C12,IFM[[MES]:[MES]],Cuadro_1!$J$8,IFM[[AÑO]:[AÑO]],Cuadro_1!$L$8)/1000 -> 1528.7746 | J12: =SUMIFS(IFM[[GastosdeAdquision]:[GastosdeAdquision]],IFM[[Nombre Empresa]:[Nombre Empresa]],$C12,IFM[[MES]:[MES]],Cuadro_1!$J$8,IFM[[AÑO]:[AÑO]],Cuadro_1!$L$8)/1000 -> 0 | K12: =SUMIFS(IFM[[Gastosdeadministracion]:[Gastosdeadministracion]],IFM[[Nombre Empresa]:[Nombre Empresa]],$C12,IFM[[MES]:[MES]],Cuadro_1!$J$8,IFM[[AÑO]:[AÑO]],Cuadro_1!$L$8)/1000 -> 66352.154
A13: =+D13 -> 100359.11 | B13: 4 | C13: Andes C.A., Seguros | D13: =SUMIFS(IFM[[PrimasNetasCobradas]:[PrimasNetasCobradas]],IFM[[Nombre Empresa]:[Nombre Empresa]],$C13,IFM[[MES]:[MES]],Cuadro_1!$J$8,IFM[[AÑO]:[AÑO]],Cuadro_1!$L$8)/1000 -> 100359.11 | E13: =SUMIFS(IFM[[SiniestrosPagados_NetosdeSalvamento]:[SiniestrosPagados_NetosdeSalvamento]],IFM[[Nombre Empresa]:[Nombre Empresa]],$C13,IFM[[MES]:[MES]],Cuadro_1!$J$8,IFM[[AÑO]:[AÑO]],Cuadro_1!$L$8)/1000 -> 10818.564 | F13: =SUMIFS(IFM[[ReservasdeSiniestrosPendientesBrutas]:[ReservasdeSiniestrosPendientesBrutas]],IFM[[Nombre Empresa]:[Nombre Empresa]],$C13,IFM[[MES]:[MES]],Cuadro_1!$J$8,IFM[[AÑO]:[AÑO]],Cuadro_1!$L$8)/1000 -> 15098.06 | G13: =SUMIFS(IFM[[SiniestrosPendientes]:[SiniestrosPendientes]],IFM[[Nombre Empresa]:[Nombre Empresa]],$C13,IFM[[MES]:[MES]],Cuadro_1!$J$8,IFM[[AÑO]:[AÑO]],Cuadro_1!$L$8)/1000 -> 15098.06 | H13: =+E13+F13 -> 25916.624 | I13: =SUMIFS(IFM[[Comisiones]:[Comisiones]],IFM[[Nombre Empresa]:[Nombre Empresa]],$C13,IFM[[MES]:[MES]],Cuadro_1!$J$8,IFM[[AÑO]:[AÑO]],Cuadro_1!$L$8)/1000 -> 11083.146 | J13: =SUMIFS(IFM[[GastosdeAdquision]:[GastosdeAdquision]],IFM[[Nombre Empresa]:[Nombre Empresa]],$C13,IFM[[MES]:[MES]],Cuadro_1!$J$8,IFM[[AÑO]:[AÑO]],Cuadro_1!$L$8)/1000 -> 8539.0285 | K13: =SUMIFS(IFM[[Gastosdeadministracion]:[Gastosdeadministracion]],IFM[[Nombre Empresa]:[Nombre Empresa]],$C13,IFM[[MES]:[MES]],Cuadro_1!$J$8,IFM[[AÑO]:[AÑO]],Cuadro_1!$L$8)/1000 -> 72529.982
A14: =+D14 -> 74294.113 | B14: 5 | C14: Aseguradora Nacional Unida Uniseguros, S.A. | D14: =SUMIFS(IFM[[PrimasNetasCobradas]:[PrimasNetasCobradas]],IFM[[Nombre Empresa]:[Nombre Empresa]],$C14,IFM[[MES]:[MES]],Cuadro_1!$J$8,IFM[[AÑO]:[AÑO]],Cuadro_1!$L$8)/1000 -> 74294.113 | E14: =SUMIFS(IFM[[SiniestrosPagados_NetosdeSalvamento]:[SiniestrosPagados_NetosdeSalvamento]],IFM[[Nombre Empresa]:[Nombre Empresa]],$C14,IFM[[MES]:[MES]],Cuadro_1!$J$8,IFM[[AÑO]:[AÑO]],Cuadro_1!$L$8)/1000 -> 17148.987 | F14: =SUMIFS(IFM[[ReservasdeSiniestrosPendientesBrutas]:[ReservasdeSiniestrosPendientesBrutas]],IFM[[Nombre Empresa]:[Nombre Empresa]],$C14,IFM[[MES]:[MES]],Cuadro_1!$J$8,IFM[[AÑO]:[AÑO]],Cuadro_1!$L$8)/1000 -> 10935.352 | G14: =SUMIFS(IFM[[SiniestrosPendientes]:[SiniestrosPendientes]],IFM[[Nombre Empresa]:[Nombre Empresa]],$C14,IFM[[MES]:[MES]],Cuadro_1!$J$8,IFM[[AÑO]:[AÑO]],Cuadro_1!$L$8)/1000 -> 1418.4021 | H14: =+E14+F14 -> 28084.338 | I14: =SUMIFS(IFM[[Comisiones]:[Comisiones]],IFM[[Nombre Empresa]:[Nombre Empresa]],$C14,IFM[[MES]:[MES]],Cuadro_1!$J$8,IFM[[AÑO]:[AÑO]],Cuadro_1!$L$8)/1000 -> 8348.5602 | J14: =SUMIFS(IFM[[GastosdeAdquision]:[GastosdeAdquision]],IFM[[Nombre Empresa]:[Nombre Empresa]],$C14,IFM[[MES]:[MES]],Cuadro_1!$J$8,IFM[[AÑO]:[AÑO]],Cuadro_1!$L$8)/1000 -> 9040.4409 | K14: =SUMIFS(IFM[[Gastosdeadministracion]:[Gastosdeadministracion]],IFM[[Nombre Empresa]:[Nombre Empresa]],$C14,IFM[[MES]:[MES]],Cuadro_1!$J$8,IFM[[AÑO]:[AÑO]],Cuadro_1!$L$8)/1000 -> 46304.778
A15: =+D15 -> 217229.65 | B15: 6 | C15: Atrio Seguros S.A. | D15: =SUMIFS(IFM[[PrimasNetasCobradas]:[PrimasNetasCobradas]],IFM[[Nombre Empresa]:[Nombre Empresa]],$C15,IFM[[MES]:[MES]],Cuadro_1!$J$8,IFM[[AÑO]:[AÑO]],Cuadro_1!$L$8)/1000 -> 217229.65 | E15: =SUMIFS(IFM[[SiniestrosPagados_NetosdeSalvamento]:[SiniestrosPagados_NetosdeSalvamento]],IFM[[Nombre Empresa]:[Nombre Empresa]],$C15,IFM[[MES]:[MES]],Cuadro_1!$J$8,IFM[[AÑO]:[AÑO]],Cuadro_1!$L$8)/1000 -> 41051.31 | F15: =SUMIFS(IFM[[ReservasdeSiniestrosPendientesBrutas]:[ReservasdeSiniestrosPendientesBrutas]],IFM[[Nombre Empresa]:[Nombre Empresa]],$C15,IFM[[MES]:[MES]],Cuadro_1!$J$8,IFM[[AÑO]:[AÑO]],Cuadro_1!$L$8)/1000 -> 35272.619 | G15: =SUMIFS(IFM[[SiniestrosPendientes]:[SiniestrosPendientes]],IFM[[Nombre Empresa]:[Nombre Empresa]],$C15,IFM[[MES]:[MES]],Cuadro_1!$J$8,IFM[[AÑO]:[AÑO]],Cuadro_1!$L$8)/1000 -> 24144.992 | H15: =+E15+F15 -> 76323.93 | I15: =SUMIFS(IFM[[Comisiones]:[Comisiones]],IFM[[Nombre Empresa]:[Nombre Empresa]],$C15,IFM[[MES]:[MES]],Cuadro_1!$J$8,IFM[[AÑO]:[AÑO]],Cuadro_1!$L$8)/1000 -> 27942.193 | J15: =SUMIFS(IFM[[GastosdeAdquision]:[GastosdeAdquision]],IFM[[Nombre Empresa]:[Nombre Empresa]],$C15,IFM[[MES]:[MES]],Cuadro_1!$J$8,IFM[[AÑO]:[AÑO]],Cuadro_1!$L$8)/1000 -> 16002.289 | K15: =SUMIFS(IFM[[Gastosdeadministracion]:[Gastosdeadministracion]],IFM[[Nombre Empresa]:[Nombre Empresa]],$C15,IFM[[MES]:[MES]],Cuadro_1!$J$8,IFM[[AÑO]:[AÑO]],Cuadro_1!$L$8)/1000 -> 84569.755
A16: =+D16 -> 0 | B16: 7 | C16: Ávila C.A., de Seguros | D16: =SUMIFS(IFM[[PrimasNetasCobradas]:[PrimasNetasCobradas]],IFM[[Nombre Empresa]:[Nombre Empresa]],$C16,IFM[[MES]:[MES]],Cuadro_1!$J$8,IFM[[AÑO]:[AÑO]],Cuadro_1!$L$8)/1000 -> 0 | E16: =SUMIFS(IFM[[SiniestrosPagados_NetosdeSalvamento]:[SiniestrosPagados_NetosdeSalvamento]],IFM[[Nombre Empresa]:[Nombre Empresa]],$C16,IFM[[MES]:[MES]],Cuadro_1!$J$8,IFM[[AÑO]:[AÑO]],Cuadro_1!$L$8)/1000 -> 0 | F16: =SUMIFS(IFM[[ReservasdeSiniestrosPendientesBrutas]:[ReservasdeSiniestrosPendientesBrutas]],IFM[[Nombre Empresa]:[Nombre Empresa]],$C16,IFM[[MES]:[MES]],Cuadro_1!$J$8,IFM[[AÑO]:[AÑO]],Cuadro_1!$L$8)/1000 -> 0 | G16: =SUMIFS(IFM[[SiniestrosPendientes]:[SiniestrosPendientes]],IFM[[Nombre Empresa]:[Nombre Empresa]],$C16,IFM[[MES]:[MES]],Cuadro_1!$J$8,IFM[[AÑO]:[AÑO]],Cuadro_1!$L$8)/1000 -> 0 | H16: =+E16+F16 -> 0 | I16: =SUMIFS(IFM[[Comisiones]:[Comisiones]],IFM[[Nombre Empresa]:[Nombre Empresa]],$C16,IFM[[MES]:[MES]],Cuadro_1!$J$8,IFM[[AÑO]:[AÑO]],Cuadro_1!$L$8)/1000 -> 0 | J16: =SUMIFS(IFM[[GastosdeAdquision]:[GastosdeAdquision]],IFM[[Nombre Empresa]:[Nombre Empresa]],$C16,IFM[[MES]:[MES]],Cuadro_1!$J$8,IFM[[AÑO]:[AÑO]],Cuadro_1!$L$8)/1000 -> 0 | K16: =SUMIFS(IFM[[Gastosdeadministracion]:[Gastosdeadministracion]],IFM[[Nombre Empresa]:[Nombre Empresa]],$C16,IFM[[MES]:[MES]],Cuadro_1!$J$8,IFM[[AÑO]:[AÑO]],Cuadro_1!$L$8)/1000 -> 0
A17: =+D17 -> 1408959.8 | B17: 8 | C17: Banesco Seguros C.A. | D17: =SUMIFS(IFM[[PrimasNetasCobradas]:[PrimasNetasCobradas]],IFM[[Nombre Empresa]:[Nombre Empresa]],$C17,IFM[[MES]:[MES]],Cuadro_1!$J$8,IFM[[AÑO]:[AÑO]],Cuadro_1!$L$8)/1000 -> 1408959.8 | E17: =SUMIFS(IFM[[SiniestrosPagados_NetosdeSalvamento]:[SiniestrosPagados_NetosdeSalvamento]],IFM[[Nombre Empresa]:[Nombre Empresa]],$C17,IFM[[MES]:[MES]],Cuadro_1!$J$8,IFM[[AÑO]:[AÑO]],Cuadro_1!$L$8)/1000 -> 386450.89 | F17: =SUMIFS(IFM[[ReservasdeSiniestrosPendientesBrutas]:[ReservasdeSiniestrosPendientesBrutas]],IFM[[Nombre Empresa]:[Nombre Empresa]],$C17,IFM[[MES]:[MES]],Cuadro_1!$J$8,IFM[[AÑO]:[AÑO]],Cuadro_1!$L$8)/1000 -> 162821.98 | G17: =SUMIFS(IFM[[SiniestrosPendientes]:[SiniestrosPendientes]],IFM[[Nombre Empresa]:[Nombre Empresa]],$C17,IFM[[MES]:[MES]],Cuadro_1!$J$8,IFM[[AÑO]:[AÑO]],Cuadro_1!$L$8)/1000 -> 162821.94 | H17: =+E17+F17 -> 549272.87 | I17: =SUMIFS(IFM[[Comisiones]:[Comisiones]],IFM[[Nombre Empresa]:[Nombre Empresa]],$C17,IFM[[MES]:[MES]],Cuadro_1!$J$8,IFM[[AÑO]:[AÑO]],Cuadro_1!$L$8)/1000 -> 134974.12 | J17: =SUMIFS(IFM[[GastosdeAdquision]:[GastosdeAdquision]],IFM[[Nombre Empresa]:[Nombre Empresa]],$C17,IFM[[MES]:[MES]],Cuadro_1!$J$8,IFM[[AÑO]:[AÑO]],Cuadro_1!$L$8)/1000 -> 43396.879 | K17: =SUMIFS(IFM[[Gastosdeadministracion]:[Gastosdeadministracion]],IFM[[Nombre Empresa]:[Nombre Empresa]],$C17,IFM[[MES]:[MES]],Cuadro_1!$J$8,IFM[[AÑO]:[AÑO]],Cuadro_1!$L$8)/1000 -> 391681.86
A18: =+D18 -> 88404.835 | B18: 9 | C18: BBVA Seguros,C.A. | D18: =SUMIFS(IFM[[PrimasNetasCobradas]:[PrimasNetasCobradas]],IFM[[Nombre Empresa]:[Nombre Empresa]],$C18,IFM[[MES]:[MES]],Cuadro_1!$J$8,IFM[[AÑO]:[AÑO]],Cuadro_1!$L$8)/1000 -> 88404.835 | E18: =SUMIFS(IFM[[SiniestrosPagados_NetosdeSalvamento]:[SiniestrosPagados_NetosdeSalvamento]],IFM[[Nombre Empresa]:[Nombre Empresa]],$C18,IFM[[MES]:[MES]],Cuadro_1!$J$8,IFM[[AÑO]:[AÑO]],Cuadro_1!$L$8)/1000 -> 20588.473 | F18: =SUMIFS(IFM[[ReservasdeSiniestrosPendientesBrutas]:[ReservasdeSiniestrosPendientesBrutas]],IFM[[Nombre Empresa]:[Nombre Empresa]],$C18,IFM[[MES]:[MES]],Cuadro_1!$J$8,IFM[[AÑO]:[AÑO]],Cuadro_1!$L$8)/1000 -> 2515.952 | G18: =SUMIFS(IFM[[SiniestrosPendientes]:[SiniestrosPendientes]],IFM[[Nombre Empresa]:[Nombre Empresa]],$C18,IFM[[MES]:[MES]],Cuadro_1!$J$8,IFM[[AÑO]:[AÑO]],Cuadro_1!$L$8)/1000 -> 2515.952 | H18: =+E18+F18 -> 23104.425 | I18: =SUMIFS(IFM[[Comisiones]:[Comisiones]],IFM[[Nombre Empresa]:[Nombre Empresa]],$C18,IFM[[MES]:[MES]],Cuadro_1!$J$8,IFM[[AÑO]:[AÑO]],Cuadro_1!$L$8)/1000 -> 0 | J18: =SUMIFS(IFM[[GastosdeAdquision]:[GastosdeAdquision]],IFM[[Nombre Empresa]:[Nombre Empresa]],$C18,IFM[[MES]:[MES]],Cuadro_1!$J$8,IFM[[AÑO]:[AÑO]],Cuadro_1!$L$8)/1000 -> 0 | K18: =SUMIFS(IFM[[Gastosdeadministracion]:[Gastosdeadministracion]],IFM[[Nombre Empresa]:[Nombre Empresa]],$C18,IFM[[MES]:[MES]],Cuadro_1!$J$8,IFM[[AÑO]:[AÑO]],Cuadro_1!$L$8)/1000 -> 67525.167
A19: =+D19 -> 3139.5409 | B19: 10 | C19: Bolivariana de Seguros y Reaseguros, S.A. | D19: =SUMIFS(IFM[[PrimasNetasCobradas]:[PrimasNetasCobradas]],IFM[[Nombre Empresa]:[Nombre Empresa]],$C19,IFM[[MES]:[MES]],Cuadro_1!$J$8,IFM[[AÑO]:[AÑO]],Cuadro_1!$L$8)/1000 -> 3139.5409 | E19: =SUMIFS(IFM[[SiniestrosPagados_NetosdeSalvamento]:[SiniestrosPagados_NetosdeSalvamento]],IFM[[Nombre Empresa]:[Nombre Empresa]],$C19,IFM[[MES]:[MES]],Cuadro_1!$J$8,IFM[[AÑO]:[AÑO]],Cuadro_1!$L$8)/1000 -> 0 | F19: =SUMIFS(IFM[[ReservasdeSiniestrosPendientesBrutas]:[ReservasdeSiniestrosPendientesBrutas]],IFM[[Nombre Empresa]:[Nombre Empresa]],$C19,IFM[[MES]:[MES]],Cuadro_1!$J$8,IFM[[AÑO]:[AÑO]],Cuadro_1!$L$8)/1000 -> 0.06961 | G19: =SUMIFS(IFM[[SiniestrosPendientes]:[SiniestrosPendientes]],IFM[[Nombre Empresa]:[Nombre Empresa]],$C19,IFM[[MES]:[MES]],Cuadro_1!$J$8,IFM[[AÑO]:[AÑO]],Cuadro_1!$L$8)/1000 -> 0.06961 | H19: =+E19+F19 -> 0.06961 | I19: =SUMIFS(IFM[[Comisiones]:[Comisiones]],IFM[[Nombre Empresa]:[Nombre Empresa]],$C19,IFM[[MES]:[MES]],Cuadro_1!$J$8,IFM[[AÑO]:[AÑO]],Cuadro_1!$L$8)/1000 -> 0 | J19: =SUMIFS(IFM[[GastosdeAdquision]:[GastosdeAdquision]],IFM[[Nombre Empresa]:[Nombre Empresa]],$C19,IFM[[MES]:[MES]],Cuadro_1!$J$8,IFM[[AÑO]:[AÑO]],Cuadro_1!$L$8)/1000 -> 0 | K19: =SUMIFS(IFM[[Gastosdeadministracion]:[Gastosdeadministracion]],IFM[[Nombre Empresa]:[Nombre Empresa]],$C19,IFM[[MES]:[MES]],Cuadro_1!$J$8,IFM[[AÑO]:[AÑO]],Cuadro_1!$L$8)/1000 -> 924.5732
